Workbook

Sheet ScreenTime vs MentalWellness
A1: user_id | B1: age | C1: gender | D1: occupation | E1: work_mode | F1: screen_time_hours | G1: work_screen_hours | H1: leisure_screen_hours | I1: sleep_hours | J1: sleep_quality_1_5 | K1: stress_level_0_10 | L1: productivity_0_100 | M1: exercise_minutes_per_week | N1: social_hours_per_week | O1: mental_wellness_index_0_100
A2: U0001 | B2: 33 | C2: Female | D2: Employed | E2: Remote | F2: 10.79 | G2: 5.44 | H2: 5.35 | I2: 6.63 | J2: 1 | K2: 9.3 | L2: 44.7 | M2: 127 | N2: 0.7 | O2: 9.3
A3: U0002 | B3: 28 | C3: Female | D3: Employed | E3: In-person | F3: 7.4 | G3: 0.37 | H3: 7.03 | I3: 8.05 | J3: 3 | K3: 5.7 | L3: 78 | M3: 74 | N3: 2.1 | O3: 56.2
A4: U0003 | B4: 35 | C4: Female | D4: Employed | E4: Hybrid | F4: 9.78 | G4: 1.09 | H4: 8.69 | I4: 6.48 | J4: 1 | K4: 9.1 | L4: 51.8 | M4: 67 | N4: 8 | O4: 3.6
A5: U0004 | B5: 42 | C5: Male | D5: Employed | E5: Hybrid | F5: 11.13 | G5: 0.56 | H5: 10.57 | I5: 6.89 | J5: 1 | K5: 10 | L5: 37 | M5: 0 | N5: 5.7 | O5: 0
A6: U0005 | B6: 28 | C6: Male | D6: Student | E6: Remote | F6: 13.22 | G6: 4.09 | H6: 9.13 | I6: 5.79 | J6: 1 | K6: 10 | L6: 38.5 | M6: 0 | N6: 10.1 | O6: 0
A7: U0006 | B7: 28 | C7: Non-binary/Other | D7: Self-employed | E7: Hybrid | F7: 9.83 | G7: 0.53 | H7: 9.3 | I7: 7.19 | J7: 1 | K7: 10 | L7: 44 | M7: 71 | N7: 10.3 | O7: 5
A8: U0007 | B8: 42 | C8: Non-binary/Other | D8: Retired | E8: Remote | F8: 6.02 | G8: 2.82 | H8: 3.2 | I8: 7.44 | J8: 2 | K8: 6.1 | L8: 64.8 | M8: 141 | N8: 4.7 | O8: 43.7
A9: U0008 | B9: 36 | C9: Male | D9: Employed | E9: In-person | F9: 6.21 | G9: 0.75 | H9: 5.46 | I9: 6.78 | J9: 2 | K9: 5.4 | L9: 87 | M9: 51 | N9: 18.7 | O9: 54.3
A10: U0009 | B10: 26 | C10: Male | D10: Student | E10: In-person | F10: 6.28 | G10: 0.67 | H10: 5.61 | I10: 8.48 | J10: 4 | K10: 1.6 | L10: 91.7 | M10: 149 | N10: 10.1 | O10: 86.8
A11: U0010 | B11: 34 | C11: Male | D11: Employed | E11: Hybrid | F11: 9.37 | G11: 0.84 | H11: 8.53 | I11: 7.78 | J11: 2 | K11: 10 | L11: 42.2 | M11: 50 | N11: 12.7 | O11: 10.7
A12: U0011 | B12: 26 | C12: Male | D12: Student | E12: Remote | F12: 9.87 | G12: 3.02 | H12: 6.85 | I12: 6.4 | J12: 1 | K12: 8.8 | L12: 55.9 | M12: 87 | N12: 6.2 | O12: 21.8
A13: U0012 | B13: 26 | C13: Female | D13: Unemployed | E13: Hybrid | F13: 4.96 | G13: 0.25 | H13: 4.71 | I13: 8.01 | J13: 3 | K13: 4.6 | L13: 88.4 | M13: 188 | N13: 12.5 | O13: 74.3
... A401: U0400 | B401: 39 | C401: Female | D401: Employed | E401: Remote | F401: 8.86 | G401: 3.82 | H401: 5.04 | I401: 6.55 | J401: 1 | K401: 10 | L401: 41.4 | M401: 88 | N401: 9.8 | O401: 8.4

Sheet ScreenTime vs MentalWellness_An
A1: user_id | B1: age | C1: gender | D1: occupation | E1: work_mode | F1: screen_time_hours | G1: work_screen_hours | H1: leisure_screen_hours | I1: sleep_hours | J1: sleep_quality_1_5 | K1: stress_level_0_10 | L1: productivity_0_100 | M1: exercise_minutes_per_week | N1: social_hours_per_week | O1: mental_wellness_index_0_100 | P1: check total screen time = leisure screen + work screen | Q1: Leisure screen group | R1: Total Screen Group | S1: HighScreenExerciseGroup | T1: High Screen Social Group | AA1: work_screen_hours | AB1: Log_transformed_work_screen_hours
A2: U0001 | B2: 33 | C2: Female | D2: Employed | E2: Remote | F2: 10.79 | G2: 5.44 | H2: 5.35 | I2: 6.63 | J2: 1 | K2: 9.3 | L2: 44.7 | M2: 127 | N2: 0.7 | O2: 9.3 | P2: =F2-G2-H2 -> 0 | Q2: =IF(H2<=6.7,"Low Leisure Screen","High Leisure Screen") -> Low Leisure Screen | R2: =IF(F2<=9.09,"Low Total Screen","High Total Screen") -> High Total Screen | S2: =IF(AND(R2="High Total Screen",M2<=103),"Lower Exercise",IF(AND(R2="High Total Screen",M2>103),"Higher Exercise","")) -> Higher Exercise | T2: =IF(AND(R2="High Total Screen",N2<=7.75),"Lower Social",IF(AND(R2="High Total Screen",N2>7.75),"Higher Social","")) -> Lower Social | AA2: 5.44 | AB2: =LN(AA2+1) -> 1.8625285
A3: U0002 | B3: 28 | C3: Female | D3: Employed | E3: In-person | F3: 7.4 | G3: 0.37 | H3: 7.03 | I3: 8.05 | J3: 3 | K3: 5.7 | L3: 78 | M3: 74 | N3: 2.1 | O3: 56.2 | P3: =F3-G3-H3 -> 0 | Q3: =IF(H3<=6.7,"Low Leisure Screen","High Leisure Screen") -> High Leisure Screen | R3: =IF(F3<=9.09,"Low Total Screen","High Total Screen") -> Low Total Screen | S3: =IF(AND(R3="High Total Screen",M3<=103),"Lower Exercise",IF(AND(R3="High Total Screen",M3>103),"Higher Exercise","")) | T3: =IF(AND(R3="High Total Screen",N3<=7.75),"Lower Social",IF(AND(R3="High Total Screen",N3>7.75),"Higher Social","")) | AA3: 0.37 | AB3: =LN(AA3+1) -> 0.31481074
A4: U0003 | B4: 35 | C4: Female | D4: Employed | E4: Hybrid | F4: 9.78 | G4: 1.09 | H4: 8.69 | I4: 6.48 | J4: 1 | K4: 9.1 | L4: 51.8 | M4: 67 | N4: 8 | O4: 3.6 | P4: =F4-G4-H4 -> 0 | Q4: =IF(H4<=6.7,"Low Leisure Screen","High Leisure Screen") -> High Leisure Screen | R4: =IF(F4<=9.09,"Low Total Screen","High Total Screen") -> High Total Screen | S4: =IF(AND(R4="High Total Screen",M4<=103),"Lower Exercise",IF(AND(R4="High Total Screen",M4>103),"Higher Exercise","")) -> Lower Exercise | T4: =IF(AND(R4="High Total Screen",N4<=7.75),"Lower Social",IF(AND(R4="High Total Screen",N4>7.75),"Higher Social","")) -> Higher Social | V4: Leisure screen group | W4: Number of participants | X4: Average mental wellness | Y4: Average productivity | AA4: 1.09 | AB4: =LN(AA4+1) -> 0.73716407
A5: U0004 | B5: 42 | C5: Male | D5: Employed | E5: Hybrid | F5: 11.13 | G5: 0.56 | H5: 10.57 | I5: 6.89 | J5: 1 | K5: 10 | L5: 37 | M5: 0 | N5: 5.7 | O5: 0 | P5: =F5-G5-H5 -> 0 | Q5: =IF(H5<=6.7,"Low Leisure Screen","High Leisure Screen") -> High Leisure Screen | R5: =IF(F5<=9.09,"Low Total Screen","High Total Screen") -> High Total Screen | S5: =IF(AND(R5="High Total Screen",M5<=103),"Lower Exercise",IF(AND(R5="High Total Screen",M5>103),"Higher Exercise","")) -> Lower Exercise | T5: =IF(AND(R5="High Total Screen",N5<=7.75),"Lower Social",IF(AND(R5="High Total Screen",N5>7.75),"Higher Social","")) -> Lower Social | V5: Low Leisure Screen | W5: =COUNTIF(Q2:Q401,"Low Leisure Screen") -> 201 | X5: =AVERAGEIF(Q2:Q401,"Low Leisure Screen",O2:O401) -> 27.605473 | Y5: =AVERAGEIF(Q2:Q401,"Low Leisure Screen",L2:L401) -> 59.962189 | AA5: 0.56 | AB5: =LN(AA5+1) -> 0.44468582
A6: U0005 | B6: 28 | C6: Male | D6: Student | E6: Remote | F6: 13.22 | G6: 4.09 | H6: 9.13 | I6: 5.79 | J6: 1 | K6: 10 | L6: 38.5 | M6: 0 | N6: 10.1 | O6: 0 | P6: =F6-G6-H6 -> 0 | Q6: =IF(H6<=6.7,"Low Leisure Screen","High Leisure Screen") -> High Leisure Screen | R6: =IF(F6<=9.09,"Low Total Screen","High Total Screen") -> High Total Screen | S6: =IF(AND(R6="High Total Screen",M6<=103),"Lower Exercise",IF(AND(R6="High Total Screen",M6>103),"Higher Exercise","")) -> Lower Exercise | T6: =IF(AND(R6="High Total Screen",N6<=7.75),"Lower Social",IF(AND(R6="High Total Screen",N6>7.75),"Higher Social","")) -> Higher Social | V6: High Leisure Screen | W6: =COUNTIF(Q2:Q401,"High Leisure Screen") -> 199 | X6: =AVERAGEIF(Q2:Q401,"High Leisure Screen",O2:O401) -> 12.974874 | Y6: =AVERAGEIF(Q2:Q401,"High Leisure Screen",L2:L401) -> 48.59397 | AA6: 4.09 | AB6: =LN(AA6+1) -> 1.6272778
A7: U0006 | B7: 28 | C7: Non-binary/Other | D7: Self-employed | E7: Hybrid | F7: 9.83 | G7: 0.53 | H7: 9.3 | I7: 7.19 | J7: 1 | K7: 10 | L7: 44 | M7: 71 | N7: 10.3 | O7: 5 | P7: =F7-G7-H7 -> 0 | Q7: =IF(H7<=6.7,"Low Leisure Screen","High Leisure Screen") -> High Leisure Screen | R7: =IF(F7<=9.09,"Low Total Screen","High Total Screen") -> High Total Screen | S7: =IF(AND(R7="High Total Screen",M7<=103),"Lower Exercise",IF(AND(R7="High Total Screen",M7>103),"Higher Exercise","")) -> Lower Exercise | T7: =IF(AND(R7="High Total Screen",N7<=7.75),"Lower Social",IF(AND(R7="High Total Screen",N7>7.75),"Higher Social","")) -> Higher Social | AA7: 0.53 | AB7: =LN(AA7+1) -> 0.42526774
A8: U0007 | B8: 42 | C8: Non-binary/Other | D8: Retired | E8: Remote | F8: 6.02 | G8: 2.82 | H8: 3.2 | I8: 7.44 | J8: 2 | K8: 6.1 | L8: 64.8 | M8: 141 | N8: 4.7 | O8: 43.7 | P8: =F8-G8-H8 -> 0 | Q8: =IF(H8<=6.7,"Low Leisure Screen","High Leisure Screen") -> Low Leisure Screen | R8: =IF(F8<=9.09,"Low Total Screen","High Total Screen") -> Low Total Screen | S8: =IF(AND(R8="High Total Screen",M8<=103),"Lower Exercise",IF(AND(R8="High Total Screen",M8>103),"Higher Exercise","")) | T8: =IF(AND(R8="High Total Screen",N8<=7.75),"Lower Social",IF(AND(R8="High Total Screen",N8>7.75),"Higher Social","")) | AA8: 2.82 | AB8: =LN(AA8+1) -> 1.3402504
A9: U0008 | B9: 36 | C9: Male | D9: Employed | E9: In-person | F9: 6.21 | G9: 0.75 | H9: 5.46 | I9: 6.78 | J9: 2 | K9: 5.4 | L9: 87 | M9: 51 | N9: 18.7 | O9: 54.3 | P9: =F9-G9-H9 -> 0 | Q9: =IF(H9<=6.7,"Low Leisure Screen","High Leisure Screen") -> Low Leisure Screen | R9: =IF(F9<=9.09,"Low Total Screen","High Total Screen") -> Low Total Screen | S9: =IF(AND(R9="High Total Screen",M9<=103),"Lower Exercise",IF(AND(R9="High Total Screen",M9>103),"Higher Exercise","")) | T9: =IF(AND(R9="High Total Screen",N9<=7.75),"Lower Social",IF(AND(R9="High Total Screen",N9>7.75),"Higher Social","")) | AA9: 0.75 | AB9: =LN(AA9+1) -> 0.55961579
A10: U0009 | B10: 26 | C10: Male | D10: Student | E10: In-person | F10: 6.28 | G10: 0.67 | H10: 5.61 | I10: 8.48 | J10: 4 | K10: 1.6 | L10: 91.7 | M10: 149 | N10: 10.1 | O10: 86.8 | P10: =F10-G10-H10 -> 0 | Q10: =IF(H10<=6.7,"Low Leisure Screen","High Leisure Screen") -> Low Leisure Screen | R10: =IF(F10<=9.09,"Low Total Screen","High Total Screen") -> Low Total Screen | S10: =IF(AND(R10="High Total Screen",M10<=103),"Lower Exercise",IF(AND(R10="High Total Screen",M10>103),"Higher Exercise","")) | T10: =IF(AND(R10="High Total Screen",N10<=7.75),"Lower Social",IF(AND(R10="High Total Screen",N10>7.75),"Higher Social","")) | V10: High vs Low Leisure Screen Comparison | AA10: 0.67 | AB10: =LN(AA10+1) -> 0.51282363
A11: U0010 | B11: 34 | C11: Male | D11: Employed | E11: Hybrid | F11: 9.37 | G11: 0.84 | H11: 8.53 | I11: 7.78 | J11: 2 | K11: 10 | L11: 42.2 | M11: 50 | N11: 12.7 | O11: 10.7 | P11: =F11-G11-H11 -> 0 | Q11: =IF(H11<=6.7,"Low Leisure Screen","High Leisure Screen") -> High Leisure Screen | R11: =IF(F11<=9.09,"Low Total Screen","High Total Screen") -> High Total Screen | S11: =IF(AND(R11="High Total Screen",M11<=103),"Lower Exercise",IF(AND(R11="High Total Screen",M11>103),"Higher Exercise","")) -> Lower Exercise | T11: =IF(AND(R11="High Total Screen",N11<=7.75),"Lower Social",IF(AND(R11="High Total Screen",N11>7.75),"Higher Social","")) -> Higher Social | V11: Measure | W11: Low Leisure Screen (≤6.7h) | X11: High Leisure Screen (>6.7h) | Y11: % Difference | AA11: 0.84 | AB11: =LN(AA11+1) -> 0.60976557
A12: U0011 | B12: 26 | C12: Male | D12: Student | E12: Remote | F12: 9.87 | G12: 3.02 | H12: 6.85 | I12: 6.4 | J12: 1 | K12: 8.8 | L12: 55.9 | M12: 87 | N12: 6.2 | O12: 21.8 | P12: =F12-G12-H12 -> 0 | Q12: =IF(H12<=6.7,"Low Leisure Screen","High Leisure Screen") -> High Leisure Screen | R12: =IF(F12<=9.09,"Low Total Screen","High Total Screen") -> High Total Screen | S12: =IF(AND(R12="High Total Screen",M12<=103),"Lower Exercise",IF(AND(R12="High Total Screen",M12>103),"Higher Exercise","")) -> Lower Exercise | T12: =IF(AND(R12="High Total Screen",N12<=7.75),"Lower Social",IF(AND(R12="High Total Screen",N12>7.75),"Higher Social","")) -> Lower Social | V12: Participants | W12: 201 | X12: 199 | Y12: — | AA12: 3.02 | AB12: =LN(AA12+1) -> 1.3912819
A13: U0012 | B13: 26 | C13: Female | D13: Unemployed | E13: Hybrid | F13: 4.96 | G13: 0.25 | H13: 4.71 | I13: 8.01 | J13: 3 | K13: 4.6 | L13: 88.4 | M13: 188 | N13: 12.5 | O13: 74.3 | P13: =F13-G13-H13 -> 0 | Q13: =IF(H13<=6.7,"Low Leisure Screen","High Leisure Screen") -> Low Leisure Screen | R13: =IF(F13<=9.09,"Low Total Screen","High Total Screen") -> Low Total Screen | S13: =IF(AND(R13="High Total Screen",M13<=103),"Lower Exercise",IF(AND(R13="High Total Screen",M13>103),"Higher Exercise","")) | T13: =IF(AND(R13="High Total Screen",N13<=7.75),"Lower Social",IF(AND(R13="High Total Screen",N13>7.75),"Higher Social","")) | V13: Mental Wellness | W13: 27.61 | X13: 12.97 | Y13: 1.128 | AA13: 0.25 | AB13: =LN(AA13+1) -> 0.22314355
A14: U0013 | B14: 31 | C14: Female | D14: Student | E14: Remote | F14: 12.55 | G14: 6.8 | H14: 5.75 | I14: 6.96 | J14: 1 | K14: 10 | L14: 33 | M14: 139 | N14: 11.3 | O14: 0 | P14: =F14-G14-H14 -> 0 | Q14: =IF(H14<=6.7,"Low Leisure Screen","High Leisure Screen") -> Low Leisure Screen | R14: =IF(F14<=9.09,"Low Total Screen","High Total Screen") -> High Total Screen | S14: =IF(AND(R14="High Total Screen",M14<=103),"Lower Exercise",IF(AND(R14="High Total Screen",M14>103),"Higher Exercise","")) -> Higher Exercise | T14: =IF(AND(R14="High Total Screen",N14<=7.75),"Lower Social",IF(AND(R14="High Total Screen",N14>7.75),"Higher Social","")) -> Higher Social | V14: Productivity | W14: 59.96 | X14: 48.59 | Y14: 0.234 | AA14: 6.8 | AB14: =LN(AA14+1) -> 2.0541237
A15: U0014 | B15: 16 | C15: Female | D15: Employed | E15: Remote | F15: 7.86 | G15: 4.33 | H15: 3.53 | I15: 7.59 | J15: 2 | K15: 6.3 | L15: 70.7 | M15: 102 | N15: 8.6 | O15: 40.9 | P15: =F15-G15-H15 -> 0 | Q15: =IF(H15<=6.7,"Low Leisure Screen","High Leisure Screen") -> Low Leisure Screen | R15: =IF(F15<=9.09,"Low Total Screen","High Total Screen") -> Low Total Screen | S15: =IF(AND(R15="High Total Screen",M15<=103),"Lower Exercise",IF(AND(R15="High Total Screen",M15>103),"Higher Exercise","")) | T15: =IF(AND(R15="High Total Screen",N15<=7.75),"Lower Social",IF(AND(R15="High Total Screen",N15>7.75),"Higher Social","")) | AA15: 4.33 | AB15: =LN(AA15+1) -> 1.6733512
A16: U0015 | B16: 16 | C16: Male | D16: Employed | E16: Hybrid | F16: 9.07 | G16: 0.79 | H16: 8.28 | I16: 5.54 | J16: 1 | K16: 10 | L16: 53.2 | M16: 0 | N16: 0 | O16: 10.7 | P16: =F16-G16-H16 -> 0 | Q16: =IF(H16<=6.7,"Low Leisure Screen","High Leisure Screen") -> High Leisure Screen | R16: =IF(F16<=9.09,"Low Total Screen","High Total Screen") -> Low Total Screen | S16: =IF(AND(R16="High Total Screen",M16<=103),"Lower Exercise",IF(AND(R16="High Total Screen",M16>103),"Higher Exercise","")) | T16: =IF(AND(R16="High Total Screen",N16<=7.75),"Lower Social",IF(AND(R16="High Total Screen",N16>7.75),"Higher Social","")) | V16: Total Screen Group | W16: Participants count | AA16: 0.79 | AB16: =LN(AA16+1) -> 0.58221562
A17: U0016 | B17: 25 | C17: Male | D17: Employed | E17: Hybrid | F17: 13.49 | G17: 2.82 | H17: 10.67 | I17: 7.13 | J17: 1 | K17: 10 | L17: 37.6 | M17: 284 | N17: 2.8 | O17: 0 | P17: =F17-G17-H17 -> 0 | Q17: =IF(H17<=6.7,"Low Leisure Screen","High Leisure Screen") -> High Leisure Screen | R17: =IF(F17<=9.09,"Low Total Screen","High Total Screen") -> High Total Screen | S17: =IF(AND(R17="High Total Screen",M17<=103),"Lower Exercise",IF(AND(R17="High Total Screen",M17>103),"Higher Exercise","")) -> Higher Exercise | T17: =IF(AND(R17="High Total Screen",N17<=7.75),"Lower Social",IF(AND(R17="High Total Screen",N17>7.75),"Higher Social","")) -> Lower Social | V17: Low Total Screen | W17: =COUNTIF(R2:R401,"Low Total Screen") -> 200 | AA17: 2.82 | AB17: =LN(AA17+1) -> 1.3402504
A18: U0017 | B18: 21 | C18: Female | D18: Employed | E18: In-person | F18: 8.86 | G18: 0.82 | H18: 8.04 | I18: 6.53 | J18: 1 | K18: 10 | L18: 60.3 | M18: 223 | N18: 13.1 | O18: 10.5 | P18: =F18-G18-H18 -> 0 | Q18: =IF(H18<=6.7,"Low Leisure Screen","High Leisure Screen") -> High Leisure Screen | R18: =IF(F18<=9.09,"Low Total Screen","High Total Screen") -> Low Total Screen | S18: =IF(AND(R18="High Total Screen",M18<=103),"Lower Exercise",IF(AND(R18="High Total Screen",M18>103),"Higher Exercise","")) | T18: =IF(AND(R18="High Total Screen",N18<=7.75),"Lower Social",IF(AND(R18="High Total Screen",N18>7.75),"Higher Social","")) | V18: High Total Screen | W18: =COUNTIF(R2:R401,"High Total Screen") -> 200 | X18: =AVERAGEIF(R2:R401,"High Total Screen",M2:M401) -> 98.3 | Y18: =AVERAGEIF(R2:R401,"High Total Screen",N2:N401) -> 6.9955 | AA18: 0.82 | AB18: =LN(AA18+1) -> 0.5988365
A19: U0018 | B19: 32 | C19: Male | D19: Self-employed | E19: Hybrid | F19: 7.13 | G19: 0.82 | H19: 6.31 | I19: 7.06 | J19: 1 | K19: 7 | L19: 49 | M19: 167 | N19: 11.6 | O19: 29.5 | P19: =F19-G19-H19 -> 0 | Q19: =IF(H19<=6.7,"Low Leisure Screen","High Leisure Screen") -> Low Leisure Screen | R19: =IF(F19<=9.09,"Low Total Screen","High Total Screen") -> Low Total Screen | S19: =IF(AND(R19="High Total Screen",M19<=103),"Lower Exercise",IF(AND(R19="High Total Screen",M19>103),"Higher Exercise","")) | T19: =IF(AND(R19="High Total Screen",N19<=7.75),"Lower Social",IF(AND(R19="High Total Screen",N19>7.75),"Higher Social","")) | AA19: 0.82 | AB19: =LN(AA19+1) -> 0.5988365
A20: U0019 | B20: 22 | C20: Male | D20: Student | E20: Hybrid | F20: 8.18 | G20: 0.7 | H20: 7.48 | I20: 9.2 | J20: 3 | K20: 4.2 | L20: 85.1 | M20: 52 | N20: 11.2 | O20: 68.9 | P20: =F20-G20-H20 -> 0 | Q20: =IF(H20<=6.7,"Low Leisure Screen","High Leisure Screen") -> High Leisure Screen | R20: =IF(F20<=9.09,"Low Total Screen","High Total Screen") -> Low Total Screen | S20: =IF(AND(R20="High Total Screen",M20<=103),"Lower Exercise",IF(AND(R20="High Total Screen",M20>103),"Higher Exercise","")) | T20: =IF(AND(R20="High Total Screen",N20<=7.75),"Lower Social",IF(AND(R20="High Total Screen",N20>7.75),"Higher Social","")) | V20: Exercise ↔ Mental Wellness for high total screen users | W20: =IFERROR(__xludf.DUMMYFUNCTION("CORREL( FILTER(M2:M401,R2:R401=""High Total Screen""), FILTER(O2:O401,R2:R401=""High Total Screen"") )"),0.09839163729799255) -> 0.098391637 | AA20: 0.7 | AB20: =LN(AA20+1) -> 0.53062825
A21: U0020 | B21: 18 | C21: Female | D21: Student | E21: Remote | F21: 10.26 | G21: 5.73 | H21: 4.53 | I21: 6.98 | J21: 1 | K21: 9.4 | L21: 52 | M21: 82 | N21: 1.5 | O21: 10.8 | P21: =F21-G21-H21 -> 0 | Q21: =IF(H21<=6.7,"Low Leisure Screen","High Leisure Screen") -> Low Leisure Screen | R21: =IF(F21<=9.09,"Low Total Screen","High Total Screen") -> High Total Screen | S21: =IF(AND(R21="High Total Screen",M21<=103),"Lower Exercise",IF(AND(R21="High Total Screen",M21>103),"Higher Exercise","")) -> Lower Exercise | T21: =IF(AND(R21="High Total Screen",N21<=7.75),"Lower Social",IF(AND(R21="High Total Screen",N21>7.75),"Higher Social","")) -> Lower Social | V21: Social Hours ↔ Mental Wellness for High Total Screen users | W21: =IFERROR(__xludf.DUMMYFUNCTION("CORREL( FILTER(N2:N401,R2:R401=""High Total Screen""), FILTER(O2:O401,R2:R401=""High Total Screen"") )"),-0.12072642053556505) -> -0.12072642 | AA21: 5.73 | AB21: =LN(AA21+1) -> 1.9065751
A22: U0021 | B22: 41 | C22: Female | D22: Student | E22: Remote | F22: 10.14 | G22: 3.29 | H22: 6.85 | I22: 6.68 | J22: 1 | K22: 10 | L22: 48.1 | M22: 65 | N22: 2.8 | O22: 0 | P22: =F22-G22-H22 -> 0 | Q22: =IF(H22<=6.7,"Low Leisure Screen","High Leisure Screen") -> High Leisure Screen | R22: =IF(F22<=9.09,"Low Total Screen","High Total Screen") -> High Total Screen | S22: =IF(AND(R22="High Total Screen",M22<=103),"Lower Exercise",IF(AND(R22="High Total Screen",M22>103),"Higher Exercise","")) -> Lower Exercise | T22: =IF(AND(R22="High Total Screen",N22<=7.75),"Lower Social",IF(AND(R22="High Total Screen",N22>7.75),"Higher Social","")) -> Lower Social | AA22: 3.29 | AB22: =LN(AA22+1) -> 1.4562867
A23: U0022 | B23: 28 | C23: Male | D23: Unemployed | E23: Remote | F23: 7.52 | G23: 2.89 | H23: 4.63 | I23: 5.49 | J23: 1 | K23: 8.1 | L23: 53.1 | M23: 200 | N23: 13.2 | O23: 18.2 | P23: =F23-G23-H23 -> 0 | Q23: =IF(H23<=6.7,"Low Leisure Screen","High Leisure Screen") -> Low Leisure Screen | R23: =IF(F23<=9.09,"Low Total Screen","High Total Screen") -> Low Total Screen | S23: =IF(AND(R23="High Total Screen",M23<=103),"Lower Exercise",IF(AND(R23="High Total Screen",M23>103),"Higher Exercise","")) | T23: =IF(AND(R23="High Total Screen",N23<=7.75),"Lower Social",IF(AND(R23="High Total Screen",N23>7.75),"Higher Social","")) | V23: Exercise Group - High screen participants | W23: Participants count | X23: Average mental wellness | AA23: 2.89 | AB23: =LN(AA23+1) -> 1.3584092
A24: U0023 | B24: 30 | C24: Male | D24: Self-employed | E24: In-person | F24: 7.67 | G24: 1.65 | H24: 6.02 | I24: 8.36 | J24: 3 | K24: 5.1 | L24: 76.4 | M24: 130 | N24: 8.9 | O24: 53.5 | P24: =F24-G24-H24 -> 0 | Q24: =IF(H24<=6.7,"Low Leisure Screen","High Leisure Screen") -> Low Leisure Screen | R24: =IF(F24<=9.09,"Low Total Screen","High Total Screen") -> Low Total Screen | S24: =IF(AND(R24="High Total Screen",M24<=103),"Lower Exercise",IF(AND(R24="High Total Screen",M24>103),"Higher Exercise","")) | T24: =IF(AND(R24="High Total Screen",N24<=7.75),"Lower Social",IF(AND(R24="High Total Screen",N24>7.75),"Higher Social","")) | V24: Lower Exercise (<=103 minutes) | W24: =COUNTIF(S2:S401,"Lower Exercise") -> 116 | X24: =AVERAGEIF(S2:S401,"Lower Exercise",O2:O401) -> 9.0224138 | AA24: 1.65 | AB24: =LN(AA24+1) -> 0.97455964
A25: U0024 | B25: 18 | C25: Male | D25: Employed | E25: Remote | F25: 5.74 | G25: 2.33 | H25: 3.41 | I25: 6.34 | J25: 1 | K25: 3.7 | L25: 77.3 | M25: 63 | N25: 17.6 | O25: 48.7 | P25: =F25-G25-H25 -> 0 | Q25: =IF(H25<=6.7,"Low Leisure Screen","High Leisure Screen") -> Low Leisure Screen | R25: =IF(F25<=9.09,"Low Total Screen","High Total Screen") -> Low Total Screen | S25: =IF(AND(R25="High Total Screen",M25<=103),"Lower Exercise",IF(AND(R25="High Total Screen",M25>103),"Higher Exercise","")) | T25: =IF(AND(R25="High Total Screen",N25<=7.75),"Lower Social",IF(AND(R25="High Total Screen",N25>7.75),"Higher Social","")) | V25: Higher Exercise (>103 minutes) | W25: =COUNTIF(S2:S401,"Higher Exercise") -> 84 | X25: =AVERAGEIF(S2:S401,"Higher Exercise",O2:O401) -> 11.002381 | AA25: 2.33 | AB25: =LN(AA25+1) -> 1.2029723
A26: U0025 | B26: 25 | C26: Male | D26: Employed | E26: In-person | F26: 8.93 | G26: 0.45 | H26: 8.48 | I26: 6.21 | J26: 1 | K26: 9.8 | L26: 50.3 | M26: 69 | N26: 8.5 | O26: 0.7 | P26: =F26-G26-H26 -> 0 | Q26: =IF(H26<=6.7,"Low Leisure Screen","High Leisure Screen") -> High Leisure Screen | R26: =IF(F26<=9.09,"Low Total Screen","High Total Screen") -> Low Total Screen | S26: =IF(AND(R26="High Total Screen",M26<=103),"Lower Exercise",IF(AND(R26="High Total Screen",M26>103),"Higher Exercise","")) | T26: =IF(AND(R26="High Total Screen",N26<=7.75),"Lower Social",IF(AND(R26="High Total Screen",N26>7.75),"Higher Social","")) | AA26: 0.45 | AB26: =LN(AA26+1) -> 0.37156356
A27: U0026 | B27: 30 | C27: Male | D27: Employed | E27: Hybrid | F27: 7.05 | G27: 0.8 | H27: 6.25 | I27: 7.08 | J27: 1 | K27: 10 | L27: 51 | M27: 194 | N27: 8.6 | O27: 1.8 | P27: =F27-G27-H27 -> 0 | Q27: =IF(H27<=6.7,"Low Leisure Screen","High Leisure Screen") -> Low Leisure Screen | R27: =IF(F27<=9.09,"Low Total Screen","High Total Screen") -> Low Total Screen | S27: =IF(AND(R27="High Total Screen",M27<=103),"Lower Exercise",IF(AND(R27="High Total Screen",M27>103),"Higher Exercise","")) | T27: =IF(AND(R27="High Total Screen",N27<=7.75),"Lower Social",IF(AND(R27="High Total Screen",N27>7.75),"Higher Social","")) | V27: Social Group - High Screen Participants | W27: Participants Count | X27: Average Mental Wellness | AA27: 0.8 | AB27: =LN(AA27+1) -> 0.58778666
A28: U0027 | B28: 20 | C28: Male | D28: Student | E28: Remote | F28: 11.3 | G28: 5.17 | H28: 6.13 | I28: 7.74 | J28: 2 | K28: 10 | L28: 53.3 | M28: 197 | N28: 7.4 | O28: 4.6 | P28: =F28-G28-H28 -> 0 | Q28: =IF(H28<=6.7,"Low Leisure Screen","High Leisure Screen") -> Low Leisure Screen | R28: =IF(F28<=9.09,"Low Total Screen","High Total Screen") -> High Total Screen | S28: =IF(AND(R28="High Total Screen",M28<=103),"Lower Exercise",IF(AND(R28="High Total Screen",M28>103),"Higher Exercise","")) -> Higher Exercise | T28: =IF(AND(R28="High Total Screen",N28<=7.75),"Lower Social",IF(AND(R28="High Total Screen",N28>7.75),"Higher Social","")) -> Lower Social | V28: Lower Social Hours (<=7.75 hours) | W28: =COUNTIF(T2:T401,"Lower Social") -> 117 | X28: =AVERAGEIF(T2:T401,"Lower Social",O2:O401) -> 10.898291 | AA28: 5.17 | AB28: =LN(AA28+1) -> 1.8196988
A29: U0028 | B29: 33 | C29: Male | D29: Unemployed | E29: In-person | F29: 6.61 | G29: 0.33 | H29: 6.28 | I29: 8.06 | J29: 2 | K29: 7 | L29: 60 | M29: 227 | N29: 3.5 | O29: 42.8 | P29: =F29-G29-H29 -> 0 | Q29: =IF(H29<=6.7,"Low Leisure Screen","High Leisure Screen") -> Low Leisure Screen | R29: =IF(F29<=9.09,"Low Total Screen","High Total Screen") -> Low Total Screen | S29: =IF(AND(R29="High Total Screen",M29<=103),"Lower Exercise",IF(AND(R29="High Total Screen",M29>103),"Higher Exercise","")) | T29: =IF(AND(R29="High Total Screen",N29<=7.75),"Lower Social",IF(AND(R29="High Total Screen",N29>7.75),"Higher Social","")) | V29: Higher Social hours(>7.75 hours) | W29: =COUNTIF(T2:T401,"Higher Social") -> 83 | X29: =AVERAGEIF(T2:T401,"Higher Social",O2:O401) -> 8.3819277 | AA29: 0.33 | AB29: =LN(AA29+1) -> 0.28517894
A30: U0029 | B30: 25 | C30: Male | D30: Employed | E30: Hybrid | F30: 7.43 | G30: 0.73 | H30: 6.7 | I30: 7.11 | J30: 2 | K30: 7.6 | L30: 61.1 | M30: 164 | N30: 0 | O30: 28.9 | P30: =F30-G30-H30 -> 0 | Q30: =IF(H30<=6.7,"Low Leisure Screen","High Leisure Screen") -> Low Leisure Screen | R30: =IF(F30<=9.09,"Low Total Screen","High Total Screen") -> Low Total Screen | S30: =IF(AND(R30="High Total Screen",M30<=103),"Lower Exercise",IF(AND(R30="High Total Screen",M30>103),"Higher Exercise","")) | T30: =IF(AND(R30="High Total Screen",N30<=7.75),"Lower Social",IF(AND(R30="High Total Screen",N30>7.75),"Higher Social","")) | AA30: 0.73 | AB30: =LN(AA30+1) -> 0.54812141
A31: U0030 | B31: 27 | C31: Female | D31: Employed | E31: In-person | F31: 9.57 | G31: 0.48 | H31: 9.09 | I31: 7.18 | J31: 1 | K31: 10 | L31: 38 | M31: 81 | N31: 9.1 | O31: 0.9 | P31: =F31-G31-H31 -> 0 | Q31: =IF(H31<=6.7,"Low Leisure Screen","High Leisure Screen") -> High Leisure Screen | R31: =IF(F31<=9.09,"Low Total Screen","High Total Screen") -> High Total Screen | S31: =IF(AND(R31="High Total Screen",M31<=103),"Lower Exercise",IF(AND(R31="High Total Screen",M31>103),"Higher Exercise","")) -> Lower Exercise | T31: =IF(AND(R31="High Total Screen",N31<=7.75),"Lower Social",IF(AND(R31="High Total Screen",N31>7.75),"Higher Social","")) -> Higher Social | V31: Other Factors Associated with Mental Wellness | AA31: 0.48 | AB31: =LN(AA31+1) -> 0.39204209
A32: U0031 | B32: 25 | C32: Female | D32: Employed | E32: In-person | F32: 6.37 | G32: 0.78 | H32: 5.59 | I32: 6.91 | J32: 1 | K32: 8.5 | L32: 52.1 | M32: 0 | N32: 8.9 | O32: 11.1 | P32: =F32-G32-H32 -> 0 | Q32: =IF(H32<=6.7,"Low Leisure Screen","High Leisure Screen") -> Low Leisure Screen | R32: =IF(F32<=9.09,"Low Total Screen","High Total Screen") -> Low Total Screen | S32: =IF(AND(R32="High Total Screen",M32<=103),"Lower Exercise",IF(AND(R32="High Total Screen",M32>103),"Higher Exercise","")) | T32: =IF(AND(R32="High Total Screen",N32<=7.75),"Lower Social",IF(AND(R32="High Total Screen",N32>7.75),"Higher Social","")) | V32: Factor | W32: Correlation (r) | X32: Interpretation | AA32: 0.78 | AB32: =LN(AA32+1) -> 0.57661336
A33: U0032 | B33: 44 | C33: Female | D33: Student | E33: Remote | F33: 14.35 | G33: 7.54 | H33: 6.81 | I33: 6.5 | J33: 1 | K33: 10 | L33: 42.6 | M33: 100 | N33: 5.1 | O33: 0 | P33: =F33-G33-H33 -> 0 | Q33: =IF(H33<=6.7,"Low Leisure Screen","High Leisure Screen") -> High Leisure Screen | R33: =IF(F33<=9.09,"Low Total Screen","High Total Screen") -> High Total Screen | S33: =IF(AND(R33="High Total Screen",M33<=103),"Lower Exercise",IF(AND(R33="High Total Screen",M33>103),"Higher Exercise","")) -> Lower Exercise | T33: =IF(AND(R33="High Total Screen",N33<=7.75),"Lower Social",IF(AND(R33="High Total Screen",N33>7.75),"Higher Social","")) -> Lower Social | V33: Sleep Hours ↔ Mental Wellness | W33: =+0.581 -> 0.581 | X33: Sleep hours show a moderate positive association with mental wellness. Participants reporting more sleep tend to have higher mental-wellness scores. | AA33: 7.54 | AB33: =LN(AA33+1) -> 2.144761
A34: U0033 | B34: 29 | C34: Male | D34: Student | E34: Remote | F34: 6.89 | G34: 1.25 | H34: 5.64 | I34: 7.42 | J34: 1 | K34: 7 | L34: 60.3 | M34: 116 | N34: 0.2 | O34: 17.2 | P34: =F34-G34-H34 -> 0 | Q34: =IF(H34<=6.7,"Low Leisure Screen","High Leisure Screen") -> Low Leisure Screen | R34: =IF(F34<=9.09,"Low Total Screen","High Total Screen") -> Low Total Screen | S34: =IF(AND(R34="High Total Screen",M34<=103),"Lower Exercise",IF(AND(R34="High Total Screen",M34>103),"Higher Exercise","")) | T34: =IF(AND(R34="High Total Screen",N34<=7.75),"Lower Social",IF(AND(R34="High Total Screen",N34>7.75),"Higher Social","")) | V34: Sleep Quality ↔ Mental Wellness | W34: =+0.75 -> 0.75 | X34: Sleep quality shows a strong positive association with mental wellness. Participants reporting better sleep quality tend to have higher mental-wellness scores | AA34: 1.25 | AB34: =LN(AA34+1) -> 0.81093022
A35: U0034 | B35: 21 | C35: Male | D35: Employed | E35: Hybrid | F35: 11.38 | G35: 0.57 | H35: 10.81 | I35: 7.38 | J35: 1 | K35: 9.9 | L35: 57 | M35: 95 | N35: 11.4 | O35: 2.4 | P35: =F35-G35-H35 -> 0 | Q35: =IF(H35<=6.7,"Low Leisure Screen","High Leisure Screen") -> High Leisure Screen | R35: =IF(F35<=9.09,"Low Total Screen","High Total Screen") -> High Total Screen | S35: =IF(AND(R35="High Total Screen",M35<=103),"Lower Exercise",IF(AND(R35="High Total Screen",M35>103),"Higher Exercise","")) -> Lower Exercise | T35: =IF(AND(R35="High Total Screen",N35<=7.75),"Lower Social",IF(AND(R35="High Total Screen",N35>7.75),"Higher Social","")) -> Higher Social | V35: Stress ↔ Mental Wellness | W35: -0.914 | X35: Stress shows a very strong negative association with mental wellness. Participants with higher stress scores tend to have substantially lower mental-wellness scores. | AA35: 0.57 | AB35: =LN(AA35+1) -> 0.45107562
A36: U0035 | B36: 36 | C36: Male | D36: Student | E36: In-person | F36: 13.05 | G36: 0.65 | H36: 12.4 | I36: 7.28 | J36: 1 | K36: 10 | L36: 39.6 | M36: 86 | N36: 4.2 | O36: 0 | P36: =F36-G36-H36 -> 0 | Q36: =IF(H36<=6.7,"Low Leisure Screen","High Leisure Screen") -> High Leisure Screen | R36: =IF(F36<=9.09,"Low Total Screen","High Total Screen") -> High Total Screen | S36: =IF(AND(R36="High Total Screen",M36<=103),"Lower Exercise",IF(AND(R36="High Total Screen",M36>103),"Higher Exercise","")) -> Lower Exercise | T36: =IF(AND(R36="High Total Screen",N36<=7.75),"Lower Social",IF(AND(R36="High Total Screen",N36>7.75),"Higher Social","")) -> Lower Social | AA36: 0.65 | AB36: =LN(AA36+1) -> 0.50077529
A37: U0036 | B37: 20 | C37: Female | D37: Employed | E37: Remote | F37: 7.47 | G37: 3.01 | H37: 4.46 | I37: 7.57 | J37: 1 | K37: 8.4 | L37: 53.6 | M37: 15 | N37: 14.3 | O37: 14.8 | P37: =F37-G37-H37 -> 0 | Q37: =IF(H37<=6.7,"Low Leisure Screen","High Leisure Screen") -> Low Leisure Screen | R37: =IF(F37<=9.09,"Low Total Screen","High Total Screen") -> Low Total Screen | S37: =IF(AND(R37="High Total Screen",M37<=103),"Lower Exercise",IF(AND(R37="High Total Screen",M37>103),"Higher Exercise","")) | T37: =IF(AND(R37="High Total Screen",N37<=7.75),"Lower Social",IF(AND(R37="High Total Screen",N37>7.75),"Higher Social","")) | AA37: 3.01 | AB37: =LN(AA37+1) -> 1.3887912
A38: U0037 | B38: 31 | C38: Female | D38: Student | E38: Hybrid | F38: 9.93 | G38: 1.89 | H38: 8.04 | I38: 6.63 | J38: 1 | K38: 9.5 | L38: 45.7 | M38: 138 | N38: 15.2 | O38: 2.2 | P38: =F38-G38-H38 -> 0 | Q38: =IF(H38<=6.7,"Low Leisure Screen","High Leisure Screen") -> High Leisure Screen | R38: =IF(F38<=9.09,"Low Total Screen","High Total Screen") -> High Total Screen | S38: =IF(AND(R38="High Total Screen",M38<=103),"Lower Exercise",IF(AND(R38="High Total Screen",M38>103),"Higher Exercise","")) -> Higher Exercise | T38: =IF(AND(R38="High Total Screen",N38<=7.75),"Lower Social",IF(AND(R38="High Total Screen",N38>7.75),"Higher Social","")) -> Higher Social | AA38: 1.89 | AB38: =LN(AA38+1) -> 1.0612565
A39: U0038 | B39: 16 | C39: Female | D39: Employed | E39: Hybrid | F39: 8.08 | G39: 1.25 | H39: 6.83 | I39: 7.64 | J39: 3 | K39: 6.5 | L39: 68.1 | M39: 147 | N39: 0 | O39: 57.6 | P39: =F39-G39-H39 -> 0 | Q39: =IF(H39<=6.7,"Low Leisure Screen","High Leisure Screen") -> High Leisure Screen | R39: =IF(F39<=9.09,"Low Total Screen","High Total Screen") -> Low Total Screen | S39: =IF(AND(R39="High Total Screen",M39<=103),"Lower Exercise",IF(AND(R39="High Total Screen",M39>103),"Higher Exercise","")) | T39: =IF(AND(R39="High Total Screen",N39<=7.75),"Lower Social",IF(AND(R39="High Total Screen",N39>7.75),"Higher Social","")) | AA39: 1.25 | AB39: =LN(AA39+1) -> 0.81093022
A40: U0039 | B40: 19 | C40: Female | D40: Employed | E40: In-person | F40: 7.88 | G40: 0.39 | H40: 7.49 | I40: 7.03 | J40: 1 | K40: 9 | L40: 49.8 | M40: 153 | N40: 7.6 | O40: 17.7 | P40: =F40-G40-H40 -> 0 | Q40: =IF(H40<=6.7,"Low Leisure Screen","High Leisure Screen") -> High Leisure Screen | R40: =IF(F40<=9.09,"Low Total Screen","High Total Screen") -> Low Total Screen | S40: =IF(AND(R40="High Total Screen",M40<=103),"Lower Exercise",IF(AND(R40="High Total Screen",M40>103),"Higher Exercise","")) | T40: =IF(AND(R40="High Total Screen",N40<=7.75),"Lower Social",IF(AND(R40="High Total Screen",N40>7.75),"Higher Social","")) | AA40: 0.39 | AB40: =LN(AA40+1) -> 0.32930375
...

Sheet charts
A1: Descriptive Statistics table
A2: Variable | B2: Mean | C2: Median | D2: Std Dev | E2: Min | F2: Max
A3: Total Screen Time | B3: =AVERAGE('ScreenTime vs MentalWellness'!F2:F401) -> 9.0249 | C3: =MEDIAN('ScreenTime vs MentalWellness'!F2:F401) -> 9.09 | D3: =STDEV('ScreenTime vs MentalWellness'!F2:F401) -> 2.4910584 | E3: =MIN('ScreenTime vs MentalWellness'!F2:F401) -> 1 | F3: =MAX('ScreenTime vs MentalWellness'!F2:F401) -> 19.17
A4: Work Screen Time | B4: =AVERAGE('ScreenTime vs MentalWellness'!G2:G401) -> 2.183075 | C4: =MEDIAN('ScreenTime vs MentalWellness'!G2:G401) -> 1.455 | D4: =STDEV('ScreenTime vs MentalWellness'!G2:G401) -> 1.9313207 | E4: =MIN('ScreenTime vs MentalWellness'!G2:G401) -> 0.11 | F4: =MAX('ScreenTime vs MentalWellness'!G2:G401) -> 12.04
A5: Leisure Screen Time | B5: =AVERAGE('ScreenTime vs MentalWellness'!H2:H401) -> 6.841825 | C5: =MEDIAN('ScreenTime vs MentalWellness'!H2:H401) -> 6.7 | D5: =STDEV('ScreenTime vs MentalWellness'!H2:H401) -> 2.2208958 | E5: =MIN('ScreenTime vs MentalWellness'!H2:H401) -> 0.89 | F5: =MAX('ScreenTime vs MentalWellness'!H2:H401) -> 13.35
A6: Mental Wellness | B6: =AVERAGE('ScreenTime vs MentalWellness'!O2:O401) -> 20.32675 | C6: =MEDIAN('ScreenTime vs MentalWellness'!O2:O401) -> 14.8 | D6: =STDEV('ScreenTime vs MentalWellness'!O2:O401) -> 20.376793 | E6: =MIN('ScreenTime vs MentalWellness'!O2:O401) -> 0 | F6: =MAX('ScreenTime vs MentalWellness'!O2:O401) -> 97
A7: Productivity | B7: =AVERAGE('ScreenTime vs MentalWellness'!L2:L401) -> 54.3065 | C7: =MEDIAN('ScreenTime vs MentalWellness'!L2:L401) -> 51.75 | D7: =STDEV('ScreenTime vs MentalWellness'!L2:L401) -> 15.020054 | E7: =MIN('ScreenTime vs MentalWellness'!L2:L401) -> 20.6 | F7: =MAX('ScreenTime vs MentalWellness'!L2:L401) -> 100
A8: Stress | B8: =AVERAGE('ScreenTime vs MentalWellness'!K2:K401) -> 8.1505 | C8: =MEDIAN('ScreenTime vs MentalWellness'!K2:K401) -> 8.8 | D8: =STDEV('ScreenTime vs MentalWellness'!K2:K401) -> 2.0948438 | E8: =MIN('ScreenTime vs MentalWellness'!K2:K401) -> 0 | F8: =MAX('ScreenTime vs MentalWellness'!K2:K401) -> 10
A9: Exercise Minutes | B9: =AVERAGE('ScreenTime vs MentalWellness'!M2:M401) -> 109.4525 | C9: =MEDIAN('ScreenTime vs MentalWellness'!M2:M401) -> 103 | D9: =STDEV('ScreenTime vs MentalWellness'!M2:M401) -> 70.201984 | E9: =MIN('ScreenTime vs MentalWellness'!M2:M401) -> 0 | F9: =MAX('ScreenTime vs MentalWellness'!M2:M401) -> 372
A10: Social Hours | B10: =AVERAGE('ScreenTime vs MentalWellness'!N2:N401) -> 7.905 | C10: =MEDIAN('ScreenTime vs MentalWellness'!N2:N401) -> 7.75 | D10: =STDEV('ScreenTime vs MentalWellness'!N2:N401) -> 4.909632 | E10: =MIN('ScreenTime vs MentalWellness'!N2:N401) -> 0 | F10: =MAX('ScreenTime vs MentalWellness'!N2:N401) -> 23.9
A11: Sleep Hours | B11: =AVERAGE('ScreenTime vs MentalWellness'!I2:I401) -> 7.013175 | C11: =MEDIAN('ScreenTime vs MentalWellness'!I2:I401) -> 7.03 | D11: =STDEV('ScreenTime vs MentalWellness'!I2:I401) -> 0.8524208 | E11: =MIN('ScreenTime vs MentalWellness'!I2:I401) -> 4.64 | F11: =MAX('ScreenTime vs MentalWellness'!I2:I401) -> 9.74
A12: Sleep Quality | B12: =AVERAGE('ScreenTime vs MentalWellness'!J2:J401) -> 1.3975 | C12: =MEDIAN('ScreenTime vs MentalWellness'!J2:J401) -> 1 | D12: =STDEV('ScreenTime vs MentalWellness'!J2:J401) -> 0.65234779 | E12: =MIN('ScreenTime vs MentalWellness'!J2:J401) -> 1 | F12: =MAX('ScreenTime vs MentalWellness'!J2:J401) -> 4
A14: Correlation Analysis
A15: Relationship | B15: Correlation
A16: Total Screen Time ↔ Mental Wellness | B16: =CORREL('ScreenTime vs MentalWellness'!F2:F401,'ScreenTime vs MentalWellness'!O2:O401) -> -0.63594299
A17: Leisure Screen Time ↔ Mental Wellness | B17: =CORREL('ScreenTime vs MentalWellness'!H2:H401, 'ScreenTime vs MentalWellness'!O2:O401) -> -0.46436601
A18: Work Screen Time ↔ Mental Wellness | B18: =CORREL('ScreenTime vs MentalWellness'!G2:G401, 'ScreenTime vs MentalWellness'!O2:O401) -> -0.2862614
A19: Total Screen Time ↔ Productivity | B19: =CORREL('ScreenTime vs MentalWellness'!F2:F401, 'ScreenTime vs MentalWellness'!L2:L401) -> -0.70653739
A20: Leisure Screen Time ↔ Productivity | B20: =CORREL('ScreenTime vs MentalWellness'!H2:H401, 'ScreenTime vs MentalWellness'!L2:L401) -> -0.50055769
A21: Work Screen Time ↔ Productivity | B21: =CORREL('ScreenTime vs MentalWellness'!G2:G401, 'ScreenTime vs MentalWellness'!L2:L401) -> -0.33569743
A22: Exercise → Mental Wellness | B22: =CORREL('ScreenTime vs MentalWellness'!M2:M401, 'ScreenTime vs MentalWellness'!O2:O401) -> 0.23305006
A23: Social Hours → Mental Wellness | B23: =CORREL('ScreenTime vs MentalWellness'!N2:N401, 'ScreenTime vs MentalWellness'!O2:O401) -> 0.070399778
A24: Sleep Hours → Mental Wellness | B24: =CORREL('ScreenTime vs MentalWellness'!I2:I401, 'ScreenTime vs MentalWellness'!O2:O401) -> 0.580824
A25: Sleep Quality → Mental Wellness | B25: =CORREL('ScreenTime vs MentalWellness'!J2:J401, 'ScreenTime vs MentalWellness'!O2:O401) -> 0.7500923
A26: Stress → Mental Wellness | B26: =CORREL('ScreenTime vs MentalWellness'!K2:K401, 'ScreenTime vs MentalWellness'!O2:O401) -> -0.91381805
A28: Lifestyle Factors and Mental Wellness
A29: Relationship | B29: Correlation (r)
A30: Exercise ↔ Mental Wellness | B30: 0.233
A31: Social Hours ↔ Mental Wellness | B31: 0.07
A32: Sleep Hours ↔ Mental Wellness | B32: 0.581
A33: Sleep Quality ↔ Mental Wellness | B33: 0.75
A34: Stress ↔ Mental Wellness | B34: -0.914
A38: Visual Analysis
A74: Leisure Screen Group | B74: Mental Wellness | C74: Productivity
A75: Low Leisure Screen | B75: 27.61 | C75: 59.96
A76: High Leisure Screen | B76: 12.97 | C76: 48.59

Sheet Dashboard
A1: Screen Time, Mental Wellness & Productivity
A2: Data Analysis Case Study | 400 Participants
A4: 400 | C4: 9.02 Hrs | E4: 20.33 | G4: 54.31
A5: Participants | C5: Avg. Screen Time | E5: Avg. Mental Welness | G5: Avg. Productivity
A43: KEY INSIGHTS
A45: Screen Time & Productivity
A46: Higher total screen time was strongly negatively associated with productivity (r = -0.707).
A48: Leisure Screen Time & Wellness
A49: Higher leisure screen time was moderately negatively associated with mental wellness (r = -0.464).
A51: Low vs High Leisure Screen Use
A52: The low-leisure-screen group averaged 27.61 in mental wellness versus 12.97 for the high-leisure-screen group.
A54: Stress & Mental Wellness
A55: Stress showed the strongest observed relationship with mental wellness (r = -0.914; R² = 0.835).
A57: Note: Relationships shown are associations and should not be interpreted as causal effects.
